<mujoco model="base">
  <compiler angle="radian"/>

  <option timestep="0.0005" tolerance="1e-10" integrator="RK4" cone="elliptic" jacobian="sparse" iterations="30"/>

  <size njmax="5000" nconmax="5000"/>

  <visual>
    <quality shadowsize="2048"/>
    <map stiffness="700" fogstart="10" fogend="15" znear="0.001" zfar="40" shadowscale="0.5"/>
    <rgba haze="0.15 0.25 0.35 1"/>
  </visual>

  <statistic meansize="0.05" extent="2"/>

  <extension>
    <plugin plugin="mujoco.elasticity.cable">
      <instance name="composite">
        <config key="twist" value="7859.503362562732"/>
        <config key="bend" value="1571900.6725125466"/>
        <config key="flat" value="false"/>
      </instance>
    </plugin>
  </extension>

  <asset>
    <texture type="skybox" builtin="gradient" rgb1="1 1 0.9" rgb2="0.9 0.9 0.81" width="512" height="3072"/>
    <texture type="2d" name="texplane" builtin="checker" mark="cross" rgb1="0.2 0.3 0.4" rgb2="0.1 0.15 0.2" markrgb="0.8 0.8 0.8" width="512" height="512"/>
    <material name="matplane" texture="texplane" texuniform="true" reflectance="0.3"/>
  </asset>

  <worldbody>
    <geom name="floor" size="3 3 0.125" pos="0 0 -10" type="plane" condim="1" material="matplane"/>
    <geom name="axis_x" size="0.002 0.015" pos="0.015 0 0" quat="0.707107 0 -0.707107 0" type="capsule" rgba="1 0 0 1"/>
    <geom name="axis_y" size="0.002 0.015" pos="0 0.015 0" quat="0.707107 0.707107 0 0" type="capsule" rgba="0 1 0 1"/>
    <geom name="axis_z" size="0.002 0.015" pos="0 0 0.015" quat="0 1 0 0" type="capsule" rgba="0 0 1 1"/>
    <body name="eef_body2" pos="0.5 0 0" quat="0.467521 0.467521 0.530494 0.530494">
      <geom name="eef_geom2" size="0.006 0.006 0.012" type="box" contype="0" conaffinity="0" mass="10" rgba="0.1 0.8 0.2 0.7"/>
      <site name="eef_body2_site" pos="0 0 0" size="0.01" group="2" rgba="0 0 0 0"/>
      <body name="eef_body2_sensor">
        <site name="sensor_site2" pos="0 0 0" size="0.01" group="2" rgba="0 0 0 0"/>
      </body>
    </body>
    <body name="eef_body" pos="-0.40541 0.423375 0" quat="-0.21628 -0.21628 0.673218 0.673218">
      <geom name="eef_geom" size="0.006 0.006 0.012" type="box" contype="0" conaffinity="0" mass="10" rgba="0.8 0.2 0.1 0.7"/>
      <site name="eef_body_site" pos="0 0 0" size="0.01" group="1" rgba="0 0 0 0"/>
      <body name="eef_body_sensor">
        <site name="sensor_site1" pos="0 0 0" size="0.01" group="1" rgba="0 0 0 0"/>
      </body>
    </body>
    <body name="stiffrope" pos="0.5 0 0">
      <joint name="freejoint_A" type="free" limited="false" actuatorfrclimited="false"/>
      <body name="B_0" quat="0.467521 0.467521 0.530494 0.530494">
        <geom name="G0" size="0.003 0.03 0.0728811" pos="0.0728811 0 0" quat="0.707107 0 -0.707107 0" type="box" conaffinity="0" condim="1" solref="0.001" mass="0.0038779" rgba="0.1 0.0533333 0.673333 1"/>
        <plugin instance="composite"/>
        <body name="B_1" pos="0.145762 0 0" quat="0.989439 0 0.14495 0">
          <joint name="J_1" pos="0 0 0" type="ball" group="3" actuatorfrclimited="false" damping="0.1"/>
          <geom name="G1" size="0.003 0.03 0.072884" pos="0.072884 0 0" quat="0.707107 0 -0.707107 0" type="box" conaffinity="0" condim="1" solref="0.001" mass="0.0038779" rgba="0.1 0.0533333 0.673333 1"/>
          <plugin instance="composite"/>
          <body name="B_2" pos="0.145768 0 0" quat="0.98956 0 0.144124 0">
            <joint name="J_2" pos="0 0 0" type="ball" group="3" actuatorfrclimited="false" damping="0.1"/>
            <geom name="G2" size="0.003 0.03 0.0728869" pos="0.0728869 0 0" quat="0.707107 0 -0.707107 0" type="box" conaffinity="0" condim="1" solref="0.001" mass="0.0038779" rgba="0.1 0.0533333 0.673333 1"/>
            <plugin instance="composite"/>
            <body name="B_3" pos="0.145774 0 0" quat="0.989677 0 0.143313 0">
              <joint name="J_3" pos="0 0 0" type="ball" group="3" actuatorfrclimited="false" damping="0.1"/>
              <geom name="G3" size="0.003 0.03 0.0728898" pos="0.0728898 0 0" quat="0.707107 0 -0.707107 0" type="box" conaffinity="0" condim="1" solref="0.001" mass="0.0038779" rgba="0.1 0.0533333 0.673333 1"/>
              <plugin instance="composite"/>
              <body name="B_4" pos="0.14578 0 0" quat="0.989793 0 0.142515 0">
                <joint name="J_4" pos="0 0 0" type="ball" group="3" actuatorfrclimited="false" damping="0.1"/>
                <geom name="G4" size="0.003 0.03 0.0728926" pos="0.0728926 0 0" quat="0.707107 0 -0.707107 0" type="box" conaffinity="0" condim="1" solref="0.001" mass="0.0038779" rgba="0.1 0.0533333 0.673333 1"/>
                <plugin instance="composite"/>
                <body name="B_5" pos="0.145785 0 0" quat="0.989905 0 0.14173 0">
                  <joint name="J_5" pos="0 0 0" type="ball" group="3" actuatorfrclimited="false" damping="0.1"/>
                  <geom name="G5" size="0.003 0.03 0.0728953" pos="0.0728953 0 0" quat="0.707107 0 -0.707107 0" type="box" conaffinity="0" condim="1" solref="0.001" mass="0.0038779" rgba="0.1 0.0533333 0.673333 1"/>
                  <plugin instance="composite"/>
                  <body name="B_6" pos="0.145791 0 0" quat="0.990016 0 0.140958 0">
                    <joint name="J_6" pos="0 0 0" type="ball" group="3" actuatorfrclimited="false" damping="0.1"/>
                    <geom name="G6" size="0.003 0.03 0.0728979" pos="0.0728979 0 0" quat="0.707107 0 -0.707107 0" type="box" conaffinity="0" condim="1" solref="0.001" mass="0.0038779" rgba="0.1 0.0533333 0.673333 1"/>
                    <plugin instance="composite"/>
                    <body name="B_7" pos="0.145796 0 0" quat="0.990123 0 0.140198 0">
                      <joint name="J_7" pos="0 0 0" type="ball" group="3" actuatorfrclimited="false" damping="0.1"/>
                      <geom name="G7" size="0.003 0.03 0.0729006" pos="0.0729006 0 0" quat="0.707107 0 -0.707107 0" type="box" conaffinity="0" condim="1" solref="0.001" mass="0.0038779" rgba="0.1 0.0533333 0.673333 1"/>
                      <plugin instance="composite"/>
                      <body name="B_8" pos="0.145801 0 0" quat="0.990229 0 0.139451 0">
                        <joint name="J_8" pos="0 0 0" type="ball" group="3" actuatorfrclimited="false" damping="0.1"/>
                        <geom name="G8" size="0.003 0.03 0.0729031" pos="0.0729031 0 0" quat="0.707107 0 -0.707107 0" type="box" conaffinity="0" condim="1" solref="0.001" mass="0.0038779" rgba="0.1 0.0533333 0.673333 1"/>
                        <plugin instance="composite"/>
                        <body name="B_9" pos="0.145806 0 0" quat="0.990332 0 0.138715 0">
                          <joint name="J_9" pos="0 0 0" type="ball" group="3" actuatorfrclimited="false" damping="0.1"/>
                          <geom name="G9" size="0.003 0.03 0.0729056" pos="0.0729056 0 0" quat="0.707107 0 -0.707107 0" type="box" conaffinity="0" condim="1" solref="0.001" mass="0.0038779" rgba="0.1 0.0533333 0.673333 1"/>
                          <plugin instance="composite"/>
                          <body name="B_10" pos="0.145811 0 0" quat="0.990433 0 0.137991 0">
                            <joint name="J_10" pos="0 0 0" type="ball" group="3" actuatorfrclimited="false" damping="0.1"/>
                            <geom name="G10" size="0.003 0.03 0.072908" pos="0.072908 0 0" quat="0.707107 0 -0.707107 0" type="box" conaffinity="0" condim="1" solref="0.001" mass="0.0038779" rgba="0.1 0.0533333 0.673333 1"/>
                            <plugin instance="composite"/>
                            <body name="B_11" pos="0.145816 0 0" quat="-0.990532 0 -0.137279 0">
                              <joint name="J_11" pos="0 0 0" type="ball" group="3" actuatorfrclimited="false" damping="0.1"/>
                              <geom name="G11" size="0.003 0.03 0.0729104" pos="0.0729104 0 0" quat="0.707107 0 -0.707107 0" type="box" conaffinity="0" condim="1" solref="0.001" mass="0.0038779" rgba="0.1 0.0533333 0.673333 1"/>
                              <plugin instance="composite"/>
                              <body name="B_12" pos="0.145821 0 0" quat="0.99063 0 0.136577 0">
                                <joint name="J_12" pos="0 0 0" type="ball" group="3" actuatorfrclimited="false" damping="0.1"/>
                                <geom name="G12" size="0.003 0.03 0.0729128" pos="0.0729128 0 0" quat="0.707107 0 -0.707107 0" type="box" conaffinity="0" condim="1" solref="0.001" mass="0.0038779" rgba="0.1 0.0533333 0.673333 1"/>
                                <plugin instance="composite"/>
                                <body name="B_13" pos="0.145826 0 0" quat="0.990725 0 0.135885 0">
                                  <joint name="J_13" pos="0 0 0" type="ball" group="3" actuatorfrclimited="false" damping="0.1"/>
                                  <geom name="G13" size="0.003 0.03 0.0729151" pos="0.0729151 0 0" quat="0.707107 0 -0.707107 0" type="box" conaffinity="0" condim="1" solref="0.001" mass="0.0038779" rgba="0.1 0.0533333 0.673333 1"/>
                                  <plugin instance="composite"/>
                                  <body name="B_14" pos="0.14583 0 0" quat="0.990818 0 0.135205 0">
                                    <joint name="J_14" pos="0 0 0" type="ball" group="3" actuatorfrclimited="false" damping="0.1"/>
                                    <geom name="G14" size="0.003 0.03 0.0729173" pos="0.0729173 0 0" quat="0.707107 0 -0.707107 0" type="box" conaffinity="0" condim="1" solref="0.001" mass="0.0038779" rgba="0.1 0.0533333 0.673333 1"/>
                                    <plugin instance="composite"/>
                                    <body name="B_15" pos="0.145835 0 0" quat="0.990909 0 0.134534 0">
                                      <joint name="J_15" pos="0 0 0" type="ball" group="3" actuatorfrclimited="false" damping="0.1"/>
                                      <geom name="G15" size="0.003 0.03 0.0729195" pos="0.0729195 0 0" quat="0.707107 0 -0.707107 0" type="box" conaffinity="0" condim="1" solref="0.001" mass="0.0038779" rgba="0.1 0.0533333 0.673333 1"/>
                                      <plugin instance="composite"/>
                                      <body name="B_16" pos="0.145839 0 0" quat="0.990998 0 0.133873 0">
                                        <joint name="J_16" pos="0 0 0" type="ball" group="3" actuatorfrclimited="false" damping="0.1"/>
                                        <geom name="G16" size="0.003 0.03 0.0729217" pos="0.0729217 0 0" quat="0.707107 0 -0.707107 0" type="box" conaffinity="0" condim="1" solref="0.001" mass="0.0038779" rgba="0.1 0.0533333 0.673333 1"/>
                                        <plugin instance="composite"/>
                                        <body name="B_17" pos="0.145843 0 0" quat="0.991086 0 0.133222 0">
                                          <joint name="J_17" pos="0 0 0" type="ball" group="3" actuatorfrclimited="false" damping="0.1"/>
                                          <geom name="G17" size="0.003 0.03 0.0729238" pos="0.0729238 0 0" quat="0.707107 0 -0.707107 0" type="box" conaffinity="0" condim="1" solref="0.001" mass="0.0038779" rgba="0.1 0.0533333 0.673333 1"/>
                                          <plugin instance="composite"/>
                                          <body name="B_18" pos="0.145848 0 0" quat="0.991172 0 0.13258 0">
                                            <joint name="J_18" pos="0 0 0" type="ball" group="3" actuatorfrclimited="false" damping="0.1"/>
                                            <geom name="G18" size="0.003 0.03 0.0729259" pos="0.0729259 0 0" quat="0.707107 0 -0.707107 0" type="box" conaffinity="0" condim="1" solref="0.001" mass="0.0038779" rgba="0.1 0.0533333 0.673333 1"/>
                                            <plugin instance="composite"/>
                                            <body name="B_19" pos="0.145852 0 0" quat="0.991257 0 0.131948 0">
                                              <joint name="J_19" pos="0 0 0" type="ball" group="3" actuatorfrclimited="false" damping="0.1"/>
                                              <geom name="G19" size="0.003 0.03 0.0729279" pos="0.0729279 0 0" quat="0.707107 0 -0.707107 0" type="box" conaffinity="0" condim="1" solref="0.001" mass="0.0038779" rgba="0.1 0.0533333 0.673333 1"/>
                                              <plugin instance="composite"/>
                                              <body name="B_20" pos="0.145856 0 0" quat="0.99134 0 0.131324 0">
                                                <joint name="J_20" pos="0 0 0" type="ball" group="3" actuatorfrclimited="false" damping="0.1"/>
                                                <geom name="G20" size="0.003 0.03 0.0729299" pos="0.0729299 0 0" quat="0.707107 0 -0.707107 0" type="box" conaffinity="0" condim="1" solref="0.001" mass="0.0038779" rgba="0.1 0.0533333 0.673333 1"/>
                                                <plugin instance="composite"/>
                                                <body name="B_21" pos="0.14586 0 0" quat="0.991421 0 0.130709 0">
                                                  <joint name="J_21" pos="0 0 0" type="ball" group="3" actuatorfrclimited="false" damping="0.1"/>
                                                  <geom name="G21" size="0.003 0.03 0.0729319" pos="0.0729319 0 0" quat="0.707107 0 -0.707107 0" type="box" conaffinity="0" condim="1" solref="0.001" mass="0.0038779" rgba="0.1 0.0533333 0.673333 1"/>
                                                  <plugin instance="composite"/>
                                                  <body name="B_22" pos="0.145864 0 0" quat="0.991501 0 0.130103 0">
                                                    <joint name="J_22" pos="0 0 0" type="ball" group="3" actuatorfrclimited="false" damping="0.1"/>
                                                    <geom name="G22" size="0.003 0.03 0.0729338" pos="0.0729338 0 0" quat="0.707107 0 -0.707107 0" type="box" conaffinity="0" condim="1" solref="0.001" mass="0.0038779" rgba="0.1 0.0533333 0.673333 1"/>
                                                    <plugin instance="composite"/>
                                                    <body name="B_23" pos="0.145868 0 0" quat="0.991579 0 0.129505 0">
                                                      <joint name="J_23" pos="0 0 0" type="ball" group="3" actuatorfrclimited="false" damping="0.1"/>
                                                      <geom name="G23" size="0.003 0.03 0.0729357" pos="0.0729357 0 0" quat="0.707107 0 -0.707107 0" type="box" conaffinity="0" condim="1" solref="0.001" mass="0.0038779" rgba="0.1 0.0533333 0.673333 1"/>
                                                      <plugin instance="composite"/>
                                                      <body name="B_24" pos="0.145871 0 0" quat="0.991656 0 0.128915 0">
                                                        <joint name="J_24" pos="0 0 0" type="ball" group="3" actuatorfrclimited="false" damping="0.1"/>
                                                        <geom name="G24" size="0.003 0.03 0.0729376" pos="0.0729376 0 0" quat="0.707107 0 -0.707107 0" type="box" conaffinity="0" condim="1" solref="0.001" mass="0.0038779" rgba="0.1 0.0533333 0.673333 1"/>
                                                        <plugin instance="composite"/>
                                                        <body name="B_25" pos="0.145875 0 0" quat="0.991731 0 0.128333 0">
                                                          <joint name="J_25" pos="0 0 0" type="ball" group="3" actuatorfrclimited="false" damping="0.1"/>
                                                          <geom name="G25" size="0.003 0.03 0.0729394" pos="0.0729394 0 0" quat="0.707107 0 -0.707107 0" type="box" conaffinity="0" condim="1" solref="0.001" mass="0.0038779" rgba="0.1 0.0533333 0.673333 1"/>
                                                          <plugin instance="composite"/>
                                                          <body name="B_26" pos="0.145879 0 0" quat="0.991805 0 0.127759 0">
                                                            <joint name="J_26" pos="0 0 0" type="ball" group="3" actuatorfrclimited="false" damping="0.1"/>
                                                            <geom name="G26" size="0.003 0.03 0.0729412" pos="0.0729412 0 0" quat="0.707107 0 -0.707107 0" type="box" conaffinity="0" condim="1" solref="0.001" mass="0.0038779" rgba="0.1 0.0533333 0.673333 1"/>
                                                            <plugin instance="composite"/>
                                                            <body name="B_27" pos="0.145882 0 0" quat="0.991878 0 0.127193 0">
                                                              <joint name="J_27" pos="0 0 0" type="ball" group="3" actuatorfrclimited="false" damping="0.1"/>
                                                              <geom name="G27" size="0.003 0.03 0.072943" pos="0.072943 0 0" quat="0.707107 0 -0.707107 0" type="box" conaffinity="0" condim="1" solref="0.001" mass="0.0038779" rgba="0.1 0.0533333 0.673333 1"/>
                                                              <plugin instance="composite"/>
                                                              <body name="B_28" pos="0.145886 0 0" quat="0.99195 0 0.126634 0">
                                                                <joint name="J_28" pos="0 0 0" type="ball" group="3" actuatorfrclimited="false" damping="0.1"/>
                                                                <geom name="G28" size="0.003 0.03 0.0729447" pos="0.0729447 0 0" quat="0.707107 0 -0.707107 0" type="box" conaffinity="0" condim="1" solref="0.001" mass="0.0038779" rgba="0.1 0.0533333 0.673333 1"/>
                                                                <plugin instance="composite"/>
                                                                <body name="B_29" pos="0.145889 0 0" quat="0.99202 0 0.126082 0">
                                                                  <joint name="J_29" pos="0 0 0" type="ball" group="3" actuatorfrclimited="false" damping="0.1"/>
                                                                  <geom name="G29" size="0.003 0.03 0.0729464" pos="0.0729464 0 0" quat="0.707107 0 -0.707107 0" type="box" conaffinity="0" condim="1" solref="0.001" mass="0.0038779" rgba="0.1 0.0533333 0.673333 1"/>
                                                                  <plugin instance="composite"/>
                                                                  <body name="B_30" pos="0.145893 0 0" quat="0.992089 0 0.125538 0">
                                                                    <joint name="J_30" pos="0 0 0" type="ball" group="3" actuatorfrclimited="false" damping="0.1"/>
                                                                    <geom name="G30" size="0.003 0.03 0.0729481" pos="0.0729481 0 0" quat="0.707107 0 -0.707107 0" type="box" conaffinity="0" condim="1" solref="0.001" mass="0.0038779" rgba="0.1 0.0533333 0.673333 1"/>
                                                                    <plugin instance="composite"/>
                                                                    <body name="B_last" pos="0.145896 0 0" quat="0.992157 0 0.125001 0">
                                                                      <joint name="J_last" pos="0 0 0" type="ball" group="3" actuatorfrclimited="false" damping="0.1"/>
                                                                      <geom name="G31" size="0.003 0.03 0.0729497" pos="0.0729497 0 0" quat="0.707107 0 -0.707107 0" type="box" conaffinity="0" condim="1" solref="0.001" mass="0.0038779" rgba="0.1 0.0533333 0.673333 1"/>
                                                                      <plugin instance="composite"/>
                                                                      <body name="B_last2" pos="0.145899 0 0">
                                                                        <plugin instance="composite"/>
                                                                      </body>
                                                                    </body>
                                                                  </body>
                                                                </body>
                                                              </body>
                                                            </body>
                                                          </body>
                                                        </body>
                                                      </body>
                                                    </body>
                                                  </body>
                                                </body>
                                              </body>
                                            </body>
                                          </body>
                                        </body>
                                      </body>
                                    </body>
                                  </body>
                                </body>
                              </body>
                            </body>
                          </body>
                        </body>
                      </body>
                    </body>
                  </body>
                </body>
              </body>
            </body>
          </body>
        </body>
      </body>
    </body>
  </worldbody>

  <equality>
    <weld name="weld_end" body1="B_last" body2="eef_body_sensor" anchor="0 0 0" relpose="0.145899 0 0 1 0 0 0" torquescale="1" solref="0.001"/>
    <weld name="weld_start" body1="B_0" body2="eef_body2_sensor" anchor="0 0 0" relpose="0 0 0 1 0 0 0" torquescale="1" solref="0.001"/>
  </equality>

  <sensor>
    <torque site="sensor_site1" name="torque_A"/>
    <force site="sensor_site1" name="force_A"/>
    <torque site="sensor_site2" name="torque_B"/>
    <force site="sensor_site2" name="force_B"/>
  </sensor>
</mujoco>
