<mujoco model="base">
  <compiler angle="radian"/>

  <option timestep="0.0005" tolerance="1e-10" integrator="RK4" cone="elliptic" jacobian="sparse" iterations="30"/>

  <size njmax="5000" nconmax="5000"/>

  <visual>
    <quality shadowsize="2048"/>
    <map stiffness="700" fogstart="10" fogend="15" znear="0.001" zfar="40" shadowscale="0.5"/>
    <rgba haze="0.15 0.25 0.35 1"/>
  </visual>

  <statistic meansize="0.05" extent="2"/>

  <extension>
    <plugin plugin="mujoco.elasticity.cable">
      <instance name="composite">
        <config key="twist" value="7859.503362562732"/>
        <config key="bend" value="1571900.6725125466"/>
        <config key="flat" value="false"/>
      </instance>
    </plugin>
  </extension>

  <asset>
    <texture type="skybox" builtin="gradient" rgb1="1 1 0.9" rgb2="0.9 0.9 0.81" width="512" height="3072"/>
    <texture type="2d" name="texplane" builtin="checker" mark="cross" rgb1="0.2 0.3 0.4" rgb2="0.1 0.15 0.2" markrgb="0.8 0.8 0.8" width="512" height="512"/>
    <material name="matplane" texture="texplane" texuniform="true" reflectance="0.3"/>
  </asset>

  <worldbody>
    <geom name="floor" size="3 3 0.125" pos="0 0 -10" type="plane" condim="1" material="matplane"/>
    <geom name="axis_x" size="0.002 0.015" pos="0.015 0 0" quat="0.707107 0 -0.707107 0" type="capsule" rgba="1 0 0 1"/>
    <geom name="axis_y" size="0.002 0.015" pos="0 0.015 0" quat="0.707107 0.707107 0 0" type="capsule" rgba="0 1 0 1"/>
    <geom name="axis_z" size="0.002 0.015" pos="0 0 0.015" quat="0 1 0 0" type="capsule" rgba="0 0 1 1"/>
    <body name="eef_body2" pos="0.5 0 0" quat="0 0.65522 0.755438 0">
      <geom name="eef_geom2" size="0.006 0.006 0.012" type="box" contype="0" conaffinity="0" mass="10" rgba="0.1 0.8 0.2 0.7"/>
      <site name="eef_body2_site" pos="0 0 0" size="0.01" group="2" rgba="0 0 0 0"/>
      <body name="eef_body2_sensor">
        <site name="sensor_site2" pos="0 0 0" size="0.01" group="2" rgba="0 0 0 0"/>
      </body>
    </body>
    <body name="eef_body" pos="-2.14969 0.0235843 -2.18129" quat="0 -0.515174 0.857086 0">
      <geom name="eef_geom" size="0.006 0.006 0.012" type="box" contype="0" conaffinity="0" mass="10" rgba="0.8 0.2 0.1 0.7"/>
      <site name="eef_body_site" pos="0 0 0" size="0.01" group="1" rgba="0 0 0 0"/>
      <body name="eef_body_sensor">
        <site name="sensor_site1" pos="0 0 0" size="0.01" group="1" rgba="0 0 0 0"/>
      </body>
    </body>
    <body name="stiffrope" pos="0.5 0 0">
      <joint name="freejoint_A" type="free" limited="false" actuatorfrclimited="false"/>
      <body name="B_0" quat="0 0.65522 0.755438 0">
        <geom name="G0" size="0.003 0.03 0.0706862" pos="0.0706862 0 0" quat="0.707107 0 -0.707107 0" type="box" conaffinity="0" condim="1" solref="0.001" mass="0.0038779" rgba="0.1 0.0533333 0.673333 1"/>
        <plugin instance="composite"/>
        <body name="B_1" pos="0.0199862 -0.0197854 0.138547" quat="0.989956 0 0 -0.141372">
          <joint name="J_1" pos="0 0 0" type="ball" group="3" actuatorfrclimited="false" damping="0.1"/>
          <geom name="G1" size="0.003 0.03 0.0706862" pos="0.0706862 0 0" quat="0.707107 0 -0.707107 0" type="box" conaffinity="0" condim="1" solref="0.001" mass="0.0038779" rgba="0.1 0.0533333 0.673333 1"/>
          <plugin instance="composite"/>
          <body name="B_2" pos="0.0583607 -0.0531558 0.11728" quat="0.989956 0 0 -0.141372">
            <joint name="J_2" pos="0 0 0" type="ball" group="3" actuatorfrclimited="false" damping="0.1"/>
            <geom name="G2" size="0.003 0.03 0.0706862" pos="0.0706862 0 0" quat="0.707107 0 -0.707107 0" type="box" conaffinity="0" condim="1" solref="0.001" mass="0.0038779" rgba="0.1 0.0533333 0.673333 1"/>
            <plugin instance="composite"/>
            <body name="B_3" pos="0.0920697 -0.0698678 0.0814115" quat="0.989956 0 0 -0.141372">
              <joint name="J_3" pos="0 0 0" type="ball" group="3" actuatorfrclimited="false" damping="0.1"/>
              <geom name="G3" size="0.003 0.03 0.0706862" pos="0.0706862 0 0" quat="0.707107 0 -0.707107 0" type="box" conaffinity="0" condim="1" solref="0.001" mass="0.0038779" rgba="0.1 0.0533333 0.673333 1"/>
              <plugin instance="composite"/>
              <body name="B_4" pos="0.118418 -0.0646841 0.0421817" quat="0.989956 0 0 -0.141372">
                <joint name="J_4" pos="0 0 0" type="ball" group="3" actuatorfrclimited="false" damping="0.1"/>
                <geom name="G4" size="0.003 0.03 0.0706862" pos="0.0706862 0 0" quat="0.707107 0 -0.707107 0" type="box" conaffinity="0" condim="1" solref="0.001" mass="0.0038779" rgba="0.1 0.0533333 0.673333 1"/>
                <plugin instance="composite"/>
                <body name="B_5" pos="0.1353 -0.0392292 0.0118848" quat="0.989956 0 0 -0.141372">
                  <joint name="J_5" pos="0 0 0" type="ball" group="3" actuatorfrclimited="false" damping="0.1"/>
                  <geom name="G5" size="0.003 0.03 0.0706862" pos="0.0706862 0 0" quat="0.707107 0 -0.707107 0" type="box" conaffinity="0" condim="1" solref="0.001" mass="0.0038779" rgba="0.1 0.0533333 0.673333 1"/>
                  <plugin instance="composite"/>
                  <body name="B_6" pos="0.141365 -0.00148034 1.55027e-05" quat="0.989956 0 0 -0.141372">
                    <joint name="J_6" pos="0 0 0" type="ball" group="3" actuatorfrclimited="false" damping="0.1"/>
                    <geom name="G6" size="0.003 0.03 0.0706862" pos="0.0706862 0 0" quat="0.707107 0 -0.707107 0" type="box" conaffinity="0" condim="1" solref="0.001" mass="0.0038779" rgba="0.1 0.0533333 0.673333 1"/>
                    <plugin instance="composite"/>
                    <body name="B_7" pos="0.136128 0.0367324 0.0102936" quat="0.989956 0 0 -0.141372">
                      <joint name="J_7" pos="0 0 0" type="ball" group="3" actuatorfrclimited="false" damping="0.1"/>
                      <geom name="G7" size="0.003 0.03 0.0706862" pos="0.0706862 0 0" quat="0.707107 0 -0.707107 0" type="box" conaffinity="0" condim="1" solref="0.001" mass="0.0038779" rgba="0.1 0.0533333 0.673333 1"/>
                      <plugin instance="composite"/>
                      <body name="B_8" pos="0.120009 0.0634337 0.039498" quat="0.989956 0 0 -0.141372">
                        <joint name="J_8" pos="0 0 0" type="ball" group="3" actuatorfrclimited="false" damping="0.1"/>
                        <geom name="G8" size="0.003 0.03 0.0706862" pos="0.0706862 0 0" quat="0.707107 0 -0.707107 0" type="box" conaffinity="0" condim="1" solref="0.001" mass="0.0038779" rgba="0.1 0.0533333 0.673333 1"/>
                        <plugin instance="composite"/>
                        <body name="B_9" pos="0.0942962 0.0702557 0.0784764" quat="0.989956 0 0 -0.141372">
                          <joint name="J_9" pos="0 0 0" type="ball" group="3" actuatorfrclimited="false" damping="0.1"/>
                          <geom name="G9" size="0.003 0.03 0.0706862" pos="0.0706862 0 0" quat="0.707107 0 -0.707107 0" type="box" conaffinity="0" condim="1" solref="0.001" mass="0.0038779" rgba="0.1 0.0533333 0.673333 1"/>
                          <plugin instance="composite"/>
                          <body name="B_10" pos="0.0610446 0.0550603 0.115013" quat="0.989956 0 0 -0.141372">
                            <joint name="J_10" pos="0 0 0" type="ball" group="3" actuatorfrclimited="false" damping="0.1"/>
                            <geom name="G10" size="0.003 0.03 0.0706862" pos="0.0706862 0 0" quat="0.707107 0 -0.707107 0" type="box" conaffinity="0" condim="1" solref="0.001" mass="0.0038779" rgba="0.1 0.0533333 0.673333 1"/>
                            <plugin instance="composite"/>
                            <body name="B_11" pos="0.0229127 0.0226098 0.137659" quat="-0.989956 0 0 0.141372">
                              <joint name="J_11" pos="0 0 0" type="ball" group="3" actuatorfrclimited="false" damping="0.1"/>
                              <geom name="G11" size="0.003 0.03 0.0706862" pos="0.0706862 0 0" quat="0.707107 0 -0.707107 0" type="box" conaffinity="0" condim="1" solref="0.001" mass="0.0038779" rgba="0.1 0.0533333 0.673333 1"/>
                              <plugin instance="composite"/>
                              <body name="B_12" pos="-0.0170508 -0.0169264 0.139316" quat="0.989956 0 0 -0.141372">
                                <joint name="J_12" pos="0 0 0" type="ball" group="3" actuatorfrclimited="false" damping="0.1"/>
                                <geom name="G12" size="0.003 0.03 0.0706862" pos="0.0706862 0 0" quat="0.707107 0 -0.707107 0" type="box" conaffinity="0" condim="1" solref="0.001" mass="0.0038779" rgba="0.1 0.0533333 0.673333 1"/>
                                <plugin instance="composite"/>
                                <body name="B_13" pos="-0.0556513 -0.051158 0.119465" quat="0.989956 0 0 -0.141372">
                                  <joint name="J_13" pos="0 0 0" type="ball" group="3" actuatorfrclimited="false" damping="0.1"/>
                                  <geom name="G13" size="0.003 0.03 0.0706862" pos="0.0706862 0 0" quat="0.707107 0 -0.707107 0" type="box" conaffinity="0" condim="1" solref="0.001" mass="0.0038779" rgba="0.1 0.0533333 0.673333 1"/>
                                  <plugin instance="composite"/>
                                  <body name="B_14" pos="-0.0898027 -0.0693574 0.0843279" quat="0.989956 0 0 -0.141372">
                                    <joint name="J_14" pos="0 0 0" type="ball" group="3" actuatorfrclimited="false" damping="0.1"/>
                                    <geom name="G14" size="0.003 0.03 0.0706862" pos="0.0706862 0 0" quat="0.707107 0 -0.707107 0" type="box" conaffinity="0" condim="1" solref="0.001" mass="0.0038779" rgba="0.1 0.0533333 0.673333 1"/>
                                    <plugin instance="composite"/>
                                    <body name="B_15" pos="-0.116775 -0.065821 0.0449154" quat="0.989956 0 0 -0.141372">
                                      <joint name="J_15" pos="0 0 0" type="ball" group="3" actuatorfrclimited="false" damping="0.1"/>
                                      <geom name="G15" size="0.003 0.03 0.0706862" pos="0.0706862 0 0" quat="0.707107 0 -0.707107 0" type="box" conaffinity="0" condim="1" solref="0.001" mass="0.0038779" rgba="0.1 0.0533333 0.673333 1"/>
                                      <plugin instance="composite"/>
                                      <body name="B_16" pos="-0.134412 -0.0416571 0.0135791" quat="0.989956 0 0 -0.141372">
                                        <joint name="J_16" pos="0 0 0" type="ball" group="3" actuatorfrclimited="false" damping="0.1"/>
                                        <geom name="G16" size="0.003 0.03 0.0706862" pos="0.0706862 0 0" quat="0.707107 0 -0.707107 0" type="box" conaffinity="0" condim="1" solref="0.001" mass="0.0038779" rgba="0.1 0.0533333 0.673333 1"/>
                                        <plugin instance="composite"/>
                                        <body name="B_17" pos="-0.141303 -0.00443843 0.000139483" quat="0.989956 0 0 -0.141372">
                                          <joint name="J_17" pos="0 0 0" type="ball" group="3" actuatorfrclimited="false" damping="0.1"/>
                                          <geom name="G17" size="0.003 0.03 0.0706862" pos="0.0706862 0 0" quat="0.707107 0 -0.707107 0" type="box" conaffinity="0" condim="1" solref="0.001" mass="0.0038779" rgba="0.1 0.0533333 0.673333 1"/>
                                          <plugin instance="composite"/>
                                          <body name="B_18" pos="-0.136897 0.0341712 0.00880836" quat="0.989956 0 0 -0.141372">
                                            <joint name="J_18" pos="0 0 0" type="ball" group="3" actuatorfrclimited="false" damping="0.1"/>
                                            <geom name="G18" size="0.003 0.03 0.0706862" pos="0.0706862 0 0" quat="0.707107 0 -0.707107 0" type="box" conaffinity="0" condim="1" solref="0.001" mass="0.0038779" rgba="0.1 0.0533333 0.673333 1"/>
                                            <plugin instance="composite"/>
                                            <body name="B_19" pos="-0.121548 0.062072 0.036869" quat="0.989956 0 0 -0.141372">
                                              <joint name="J_19" pos="0 0 0" type="ball" group="3" actuatorfrclimited="false" damping="0.1"/>
                                              <geom name="G19" size="0.003 0.03 0.0706862" pos="0.0706862 0 0" quat="0.707107 0 -0.707107 0" type="box" conaffinity="0" condim="1" solref="0.001" mass="0.0038779" rgba="0.1 0.0533333 0.673333 1"/>
                                              <plugin instance="composite"/>
                                              <body name="B_20" pos="-0.0964814 0.0705202 0.0755275" quat="0.989956 0 0 -0.141372">
                                                <joint name="J_20" pos="0 0 0" type="ball" group="3" actuatorfrclimited="false" damping="0.1"/>
                                                <geom name="G20" size="0.003 0.03 0.0706862" pos="0.0706862 0 0" quat="0.707107 0 -0.707107 0" type="box" conaffinity="0" condim="1" solref="0.001" mass="0.0038779" rgba="0.1 0.0533333 0.673333 1"/>
                                                <plugin instance="composite"/>
                                                <body name="B_21" pos="-0.0637016 0.0568683 0.112669" quat="0.989956 0 0 -0.141372">
                                                  <joint name="J_21" pos="0 0 0" type="ball" group="3" actuatorfrclimited="false" damping="0.1"/>
                                                  <geom name="G21" size="0.003 0.03 0.0706862" pos="0.0706862 0 0" quat="0.707107 0 -0.707107 0" type="box" conaffinity="0" condim="1" solref="0.001" mass="0.0038779" rgba="0.1 0.0533333 0.673333 1"/>
                                                  <plugin instance="composite"/>
                                                  <body name="B_22" pos="-0.0258292 0.0253945 0.136653" quat="0.989956 0 0 -0.141372">
                                                    <joint name="J_22" pos="0 0 0" type="ball" group="3" actuatorfrclimited="false" damping="0.1"/>
                                                    <geom name="G22" size="0.003 0.03 0.0706862" pos="0.0706862 0 0" quat="0.707107 0 -0.707107 0" type="box" conaffinity="0" condim="1" solref="0.001" mass="0.0038779" rgba="0.1 0.0533333 0.673333 1"/>
                                                    <plugin instance="composite"/>
                                                    <body name="B_23" pos="0.014108 -0.0140376 0.139965" quat="0.989956 0 0 -0.141372">
                                                      <joint name="J_23" pos="0 0 0" type="ball" group="3" actuatorfrclimited="false" damping="0.1"/>
                                                      <geom name="G23" size="0.003 0.03 0.0706862" pos="0.0706862 0 0" quat="0.707107 0 -0.707107 0" type="box" conaffinity="0" condim="1" solref="0.001" mass="0.0038779" rgba="0.1 0.0533333 0.673333 1"/>
                                                      <plugin instance="composite"/>
                                                      <body name="B_24" pos="0.0529175 -0.0490705 0.121565" quat="0.989956 0 0 -0.141372">
                                                        <joint name="J_24" pos="0 0 0" type="ball" group="3" actuatorfrclimited="false" damping="0.1"/>
                                                        <geom name="G24" size="0.003 0.03 0.0706862" pos="0.0706862 0 0" quat="0.707107 0 -0.707107 0" type="box" conaffinity="0" condim="1" solref="0.001" mass="0.0038779" rgba="0.1 0.0533333 0.673333 1"/>
                                                        <plugin instance="composite"/>
                                                        <body name="B_25" pos="0.0874964 -0.0687253 0.0872203" quat="0.989956 0 0 -0.141372">
                                                          <joint name="J_25" pos="0 0 0" type="ball" group="3" actuatorfrclimited="false" damping="0.1"/>
                                                          <geom name="G25" size="0.003 0.03 0.0706862" pos="0.0706862 0 0" quat="0.707107 0 -0.707107 0" type="box" conaffinity="0" condim="1" solref="0.001" mass="0.0038779" rgba="0.1 0.0533333 0.673333 1"/>
                                                          <plugin instance="composite"/>
                                                          <body name="B_26" pos="0.11508 -0.0668424 0.0476943" quat="0.989956 0 0 -0.141372">
                                                            <joint name="J_26" pos="0 0 0" type="ball" group="3" actuatorfrclimited="false" damping="0.1"/>
                                                            <geom name="G26" size="0.003 0.03 0.0706862" pos="0.0706862 0 0" quat="0.707107 0 -0.707107 0" type="box" conaffinity="0" condim="1" solref="0.001" mass="0.0038779" rgba="0.1 0.0533333 0.673333 1"/>
                                                            <plugin instance="composite"/>
                                                            <body name="B_27" pos="0.133464 -0.044012 0.0153736" quat="0.989956 0 0 -0.141372">
                                                              <joint name="J_27" pos="0 0 0" type="ball" group="3" actuatorfrclimited="false" damping="0.1"/>
                                                              <geom name="G27" size="0.003 0.03 0.0706862" pos="0.0706862 0 0" quat="0.707107 0 -0.707107 0" type="box" conaffinity="0" condim="1" solref="0.001" mass="0.0038779" rgba="0.1 0.0533333 0.673333 1"/>
                                                              <plugin instance="composite"/>
                                                              <body name="B_28" pos="0.141179 -0.00738872 0.000387227" quat="0.989956 0 0 -0.141372">
                                                                <joint name="J_28" pos="0 0 0" type="ball" group="3" actuatorfrclimited="false" damping="0.1"/>
                                                                <geom name="G28" size="0.003 0.03 0.0706862" pos="0.0706862 0 0" quat="0.707107 0 -0.707107 0" type="box" conaffinity="0" condim="1" solref="0.001" mass="0.0038779" rgba="0.1 0.0533333 0.673333 1"/>
                                                                <plugin instance="composite"/>
                                                                <body name="B_29" pos="0.137606 0.0315501 0.0074317" quat="0.989956 0 0 -0.141372">
                                                                  <joint name="J_29" pos="0 0 0" type="ball" group="3" actuatorfrclimited="false" damping="0.1"/>
                                                                  <geom name="G29" size="0.003 0.03 0.0706862" pos="0.0706862 0 0" quat="0.707107 0 -0.707107 0" type="box" conaffinity="0" condim="1" solref="0.001" mass="0.0038779" rgba="0.1 0.0533333 0.673333 1"/>
                                                                  <plugin instance="composite"/>
                                                                  <body name="B_30" pos="0.123033 0.0606015 0.0342994" quat="0.989956 0 0 -0.141372">
                                                                    <joint name="J_30" pos="0 0 0" type="ball" group="3" actuatorfrclimited="false" damping="0.1"/>
                                                                    <geom name="G30" size="0.003 0.03 0.0706862" pos="0.0706862 0 0" quat="0.707107 0 -0.707107 0" type="box" conaffinity="0" condim="1" solref="0.001" mass="0.0038779" rgba="0.1 0.0533333 0.673333 1"/>
                                                                    <plugin instance="composite"/>
                                                                    <body name="B_last" pos="0.0986243 0.0706611 0.0725702" quat="0.989956 0 0 -0.141372">
                                                                      <joint name="J_last" pos="0 0 0" type="ball" group="3" actuatorfrclimited="false" damping="0.1"/>
                                                                      <geom name="G31" size="0.003 0.03 0.0706862" pos="0.0706862 0 0" quat="0.707107 0 -0.707107 0" type="box" conaffinity="0" condim="1" solref="0.001" mass="0.0038779" rgba="0.1 0.0533333 0.673333 1"/>
                                                                      <plugin instance="composite"/>
                                                                      <body name="B_last2" pos="0.0663307 0.0585764 0.110251">
                                                                        <plugin instance="composite"/>
                                                                      </body>
                                                                    </body>
                                                                  </body>
                                                                </body>
                                                              </body>
                                                            </body>
                                                          </body>
                                                        </body>
                                                      </body>
                                                    </body>
                                                  </body>
                                                </body>
                                              </body>
                                            </body>
                                          </body>
                                        </body>
                                      </body>
                                    </body>
                                  </body>
                                </body>
                              </body>
                            </body>
                          </body>
                        </body>
                      </body>
                    </body>
                  </body>
                </body>
              </body>
            </body>
          </body>
        </body>
      </body>
    </body>
  </worldbody>

  <equality>
    <weld name="weld_end" body1="B_last" body2="eef_body_sensor" anchor="0 0 0" relpose="0.0663307 0.0585764 0.110251 1 0 0 0" torquescale="1" solref="0.001"/>
    <weld name="weld_start" body1="B_0" body2="eef_body2_sensor" anchor="0 0 0" relpose="0 0 0 1 0 0 0" torquescale="1" solref="0.001"/>
  </equality>

  <sensor>
    <torque site="sensor_site1" name="torque_A"/>
    <force site="sensor_site1" name="force_A"/>
    <torque site="sensor_site2" name="torque_B"/>
    <force site="sensor_site2" name="force_B"/>
  </sensor>
</mujoco>
